# Promise

## 什么是 Promise

什么是 Promise？ 解决了哪些问题？(还是基于回调的方式) - 文档 promise A+ 规范 核心 三个状态

- 回调地狱 (错误捕获不好处理错误)
- 多个请求的并发问题 (all)

1. executor - 在 new Promise 的时候，是需要传递一个执行器函数,这个函数会默认立即执行，重要
2. 每个 promise 有三个状态 默认 promise 的状态是 等待态 pending fulfilled 成功态 rejected 失败态
3. 默认创建一个 Promise 是等待态,默认提供两个函数 resolve 让 Promise 变为成功态， reject 让 Promise 变为失败态
4. 每个 Promise 实例都具备一个 then 方法，then 方法中需要传递两个参数，分别是成功对应的回调和失败对应的回调函数
5. 如何让 promise 变成失败态 a.异常抛出就走失败逻辑/是失败态 b. reject('xxx')
6. 如果多次调用成功或者失败,默认会采取第一次调用的结果 如果状态变化后就不能再修改状态

## 三种状态

````js
- pending 在过程中
- resolved
- rejected

画图表示转换关系，以及转换不可逆
pending-> resolved success
pending -> rejected fail

```js
// 刚定义时，状态默认为 pending
const p1 = new Promise((resolve, reject) => {});

// 执行 resolve() 后，状态变成 resolved
const p2 = new Promise((resolve, reject) => {
  setTimeout(() => {
    resolve();
  });
});

// 执行 reject() 后，状态变成 rejected
const p3 = new Promise((resolve, reject) => {
  console.log('p3');
  setTimeout(() => {
    reject();
  });
});
console.log('p3', p3);
// p3 p3 Promise {<pending>}
````

```js
// 直接返回一个 resolved 状态
Promise.resolve(100);
// 直接返回一个 rejected 状态
Promise.reject('some error');
```

## 代码实现

```js
const ENUM = {
  PENDING: 'pending',
  FULFILLED: 'fulfilled',
  REJECTED: 'rejected',
};

/**
 * 处理 x 方法的返回结果的状态，判断x到底是 普通值 还是 promise，x的值决定了promise2的成功还是失败
 * @param {*} promise2
 * @param {*} x
 * @param {*} resolve
 * @param {*} reject
 * @returns  返还的新的 promise x是then中的返回值
 */
function resolvePromise(promise2, x, resolve, reject) {
  // 看看 这个 promise2 是成功还是失败
  // 如果x是常量 正常走 如果是promise 我们判断状态 成功 resolve 失败 reject 所以说x决定了当前promise的结果

  // 判断 可能你的promise要和别人的promise进行混用
  // 可能不同的promise库之间会进行调用，需要兼容性操作
  // 如果 promise2和x是同一个类型 或者引用值 就该让 promise2 变成失败态
  if (promise2 === x) {
    // x如果和promise2是同一个人 x永远不能成功或者失败,所以就卡住了，直接报错
    console.log('xxx');
    // return reject('123')
    return reject(
      new TypeError(`Chaining cycle detected for promise #<Promise>]`)
    );
  }
  //----  我们需要判断x的状态 判断x 是不是promise---
  // ？ 如何判断一个值是不是  promise 呢？ 先判断他是不是对象或者函数
  // 我们原生的 promise 是一个对象  别人实现的promise可能是一个函数

  if ((typeof x === 'object' && x !== null) || typeof x === 'function') {
    // 如果是一个promise,我们取一下他的then方法 但是 有可能会抛出异常
    // 因为使用 defineProperty 定义的，需要条件处理,看类型错误demo
    // 防止一个promise 既调成功又调失败
    // 为了考虑别人的promise不健壮 我们需要自己去调整判断 如果调用失败不能成功 调用成功不能失败 不能多次调用成功或者失败
    let called;
    try {
      let then = x.then;
      if (typeof then === 'function') {
        //  判断then是不是一个函数 如果then不是一个函数 说明不是 promise 可能是个对象，比如 x={then:'123'}
        //  只能认准他是一个promise了
        then.call(
          x,
          (y) => {
            if (called) return;
            called = true;
            // 如果我们的y还是一个promise的话 继续解析
            resolvePromise(promise2, y, resolve, reject);
          },
          (e) => {
            if (called) return;
            called = true;
            reject(e);
          }
        );
        //  为什么不用这种写法呢  是因为会再次取then方法   x.then(()=>{},()=>{}) 可能会报错
      } else {
        // x = {then: '12'} 普通值
        resolve(x);
      }
    } catch (e) {
      if (called) return;
      called = true;
      reject(e);
    }
  } else {
    resolve(x); // 肯定不是promise 直接成功
  }
}

class Promise {
  // constructor 等价于 我们以前写的那种函数 function Promise
  constructor(executor) {
    //executor 默认传入 一开始就执行 默认是 pending
    this.state = ENUM.PENDING;
    // 如果是等待状态 可以更改状态
    this.value = undefined;
    this.reason = undefined;

    this.onResolvedCallbacks = []; //存储成功的的所有的回调 只有pending的时候才存储
    this.onRejectedCallbacks = []; //存储失败的的所有的回调
    const resolve = (value) => {
      // 考虑传递进来的值还是 promise，直到解析出来的值是一个普通值
      if (value instanceof Promise) {
        return value.then(resolve, reject);
      }
      // 只有状态是 pending 才能改变状态
      if (this.state === ENUM.PENDING) {
        this.value = value;
        this.state = ENUM.FULFILLED;
        this.onResolvedCallbacks.forEach((fn) => fn());
      }
    };
    const reject = (reason) => {
      if (this.state === ENUM.PENDING) {
        this.reason = reason;
        this.state = ENUM.REJECTED;
        this.onRejectedCallbacks.forEach((fn) => fn());
      }
    };
    // 我们的 try catch 只能捕获同步的异常 我们在then中加了定时器，里面的异常就捕获不到了，单独捕获
    try {
      executor(resolve, reject);
    } catch (e) {
      // 标识当前有异常  那就使当前的异常作为失败的原因
      reject(e);
    }
  }

  // 只要x是一个普通值，就会让下一个promise变成成功态，调用p2的resolve将值传递下去
  // x 有可能是一个promise
  then(onFulfilled, onRejected) {
    // 默认看一下状态  调用对应的函数
    // console.log(onFulfilled, onRejected)
    // 可选参数的处理,如果then的data没有写返回值，给一个默认函数，默认向下传递，我们返回一个默认值 (val) => val
    onFulfilled =
      typeof onFulfilled === 'function' ? onFulfilled : (val) => val;
    onRejected =
      typeof onRejected === 'function'
        ? onRejected
        : (err) => {
            throw err;
          };
    // 我们要拿到成功的或者失败的返回结果 看看这个结果是什么类型？
    let promise2;
    promise2 = new Promise((resolve, reject) => {
      if (this.state === ENUM.FULFILLED) {
        setTimeout(() => {
          try {
            //调用当前then方法的结果，来判断当前这个promise2是成功还是失败
            let x = onFulfilled(this.value);
            // 解析x值    x 是普通 还是 promise 只要x是一个普通值 就会让下一个promise变成成功态
            // 如何将data向下传递？ 我们要传递给下一个then的data 就是调用resolve方法
            // 如果 是一个promise呢
            // 关键是我 promise的时候 promise2还没产生呢 我们希望new结束之后把
            // promise2传递给我们的处理函数 加一个 定时器
            resolvePromise(promise2, x, resolve, reject);
          } catch (e) {
            reject(e);
          }
        }, 0);
      }
      if (this.state === ENUM.REJECTED) {
        setTimeout(() => {
          try {
            let x = onRejected(this.reason);
            resolvePromise(promise2, x, resolve, reject);
          } catch (e) {
            // console.log(e)
            reject(e);
          }
        }, 0);
      }
      if (this.state === ENUM.PENDING) {
        // console.log('pending state')
        // 等会成功的时候 再让他执行 分别将成功和失败的回调存起来
        this.onResolvedCallbacks.push(() => {
          setTimeout(() => {
            try {
              let x = onFulfilled(this.value);
              resolvePromise(promise2, x, resolve, reject);
            } catch (e) {
              // console.log(e)
              reject(e);
            }
          }, 0);
        });
        this.onRejectedCallbacks.push(() => {
          setTimeout(() => {
            try {
              let x = onRejected(this.reason);
              resolvePromise(promise2, x, resolve, reject);
            } catch (e) {
              console.log(e);
              reject(e);
            }
          }, 0);
        });
      }
    });
    return promise2;
  }

  // promise中的catch指代的就是then中没有成功回调的一个别名而已
  catch(callback) {
    //就是一个成功的then
    return this.then(null, callback);
  }

  static resolve(value) {
    return new Promise((resolve, reject) => {
      resolve(value);
    });
  }
  static reject(err) {
    return new Promise((resolve, reject) => {
      reject(err);
    });
  }
}
/**
 * 静态方法
 * 测试脚本也是去测试dfd上面的对象的 resolve和reject方法，如果通过了，说明这个promise可用
 * @returns
 */
Promise.deferred = function () {
  let dfd = {};
  dfd.promise = new Promise((resolve, reject) => {
    dfd.resolve = resolve;
    dfd.reject = reject;
  });
  return dfd;
};

module.exports = Promise;
```

## 链式调用 - 传值穿透

```js
/**
  promise的链式调用的实现 靠的不是this 靠的是返回一个promise
  promise必须返回一个全新的promise,这样可以解决promise的状态问题
  否则可能出现promise刚开始成功，又变成了失败态
 */

let Promise = require('./promise');
let promise = new Promise((resolve, reject) => {
  resolve('hello');
});

let promise2 = promise.then((data) => {
  // 如何将data向下传递？ 我们要传递给下一个then的data 就是调用p2的resolve方法
  // 返回一个普通值
  // return data
  // 返回一个promise

  // return promise2  // 报错就好了 对应 promise2 =x的判断
  return new Promise((resolve, reject) => {
    //返回去的y又是一个promise 继续解析
    resolve(
      new Promise((resolve, reject) => {
        setTimeout(() => {
          resolve('hello 12312');
        }, 1000);
      })
    );
  });
});
promise2.then(
  (data) => {
    console.log(data, 'zl');
  },
  (err) => {
    console.log(err, 'err');
  }
);
// 穿透 不写我们默认把值传递下去 return data
promise2
  .then(null)
  .then()
  .then()
  .then((data) => {
    console.log(data);
  });
//
// Object.defineProperty(x, 'then', {
//   get () {
//     // 有抛出异常的逻辑
//     throw new Error()
//   }
// })
```

## 类型错误

```js
const Promise = require('./promise');
let promise = new Promise((resolve, reject) => {
  resolve();
});
// 我们的 Promise2和x是同一个值，要去判断，这个操作不可能发生，抛出一个类型错误，死循环了
let promise2 = promise.then(() => {
  return promise2;
});
promise2.then(
  () => {},
  (err) => {
    console.log(err);
  }
);
// Object.defineProperty(x, 'then', {
//   get() {
//     // 某种条件不满足会抛出错误
//     throw new Error('xxx');
//   },
// });
```

## then 和 catch 返回值问题

```js
const fs = require('fs');
function read(filePath) {
  return new Promise((resolve, reject) => {
    // fs.readFile(filePath, 'utf8', (err, data) => {
    //   if (err) return reject(err)
    //   resolve(data)
    // })

    resolve(1); //返回成功的情况
    // reject() // then的第二个参数返回100 走下一个then的正确
  });
}

/*
 * promise的链式调用 (如果是一个promise 就不是普通值) 

 * 成功的回调和失败的回调都可以返回一个结果
 * 1. 如果返回的是一个promise ，那么会让这个promise执行，并且采用他的状态，将成功或者失败的结果传递给外层下一个then中
 * 2. 如果返回的是一个普通值，会把这个值作为外层的下一次then的成功的回调中
 * 3. 如何让一个promise变成失败态？抛出一个错误或者返回一个reject态的promise
 *
 * 如果then方法中的成功或者失败 执行的时候发生错误 会走下一个then中的失败回调
 * 如果then方法返回了一个失败的promise 会走外层then的失败回调 其他都走成功
 * */

read('./name.txt')
  .then((data) => {
    // return 100
    // throw new Error('i am error')
    return new Promise((resolve, reject) => {
      reject('err');
    });
  })
  .catch((err) => {
    // catch就是一个语法糖，和下面的then正常写法效果一样
    return 100;
  })
  // .then(
  //   (data) => {
  //     console.log(data, 'data');
  //   },
  //   (err) => {
  //     return 100;
  //   }
  // )
  .then(
    (data) => {
      console.log(data, '我是失败的回调中返回的值');
      throw new Error('抛出异常 , 我希望这个then走到下一次then的失败');
    },
    (err) => {
      console.log(err);
    }
  )
  .then(null, (err) => {
    console.log(err, '下一次then的失败123123');
    throw new Error('我返回错误了，catch去接受');
    // return 100
  })
  .catch((err) => {
    // catch 就是 then 的别名，没有成功的then 只要上面没有捕获错误就会执行catch，
    // 如果第二个参数捕获了错误，就不会走到catch中了
    console.log(err, 'catch');
    //  catch返回了默认值 undefined的 又回到了第二种情况 走到下一个then中
  })
  .then((data) => {
    console.log(data, '最后一个then');
  });
```

## 产生一个延迟对象，减少嵌套

```js
// 返回值是promise，递归处理
let Promise = require('./promise');
// Q.deferred 可以帮我们 产生一个延迟对象
function read() {
  const dfd = Promise.deferred(); // promise为了解决嵌套问题
  fs.readFile('./na1me.txt', 'utf-8', (err, data) => {
    if (err) {
      dfd.reject(err);
    }
    dfd.resolve(data);
  });
  return dfd.promise;
}

// promise 中的 catch 指代的就是 then没有成功回调的一个别名而已
// read().then(null, (err) => {
//   console.log(err, 'tet')
// })
read().catch((err) => {
  console.log(err, '捕捉错误');
});
```

## resolve 中还是传递 promise

```js
let Promise = require('./promise');

let p = new Promise((resolve, reject) => {
  resolve(
    new Promise((resolve, reject) => {
      setTimeout(() => {
        resolve('hello');
      }, 0);
    })
  );
});
p.then((data) => {
  console.log(data);
});
```

## Promise.all

```js
/**
 * 类的静态方法
 * Promise.all 表示等待所有的promise全部成功后，才执行回调，如果有一个promise失败了，则失败
 * 1. 我们可以将 node 中的api 转换成 promise的写法 比如 fs 的promise  node的回调参数有两个 err data
 * 2. Promise.all 返回一个promise 只要有一个失败了 那就走catch 有可能返回一个promise 也有可能不是
 */
const fs = require('fs');
// promisify 把 异步的 node中的api 转换成promise的方法 只针对node
// let { promisify } = require('util');

// 高阶函数 接受一个fn 返回一个函数 函数返回一个 promise
function promisify(fn) {
  return function (...args) {
    return new Promise((resolve, reject) => {
      fn(...args, (err, data) => {
        if (err) return reject(err);
        resolve(data);
      });
    });
  };
}
let read = promisify(fs.readFile);
read('./name.txt', 'utf-8').then((data) => {
  console.log(data);
});
// 让我们的promise里面的每一个都依次执行 把结果和我们的索引做上一个映射关系
function isPromise(value) {
  if (
    (typeof value === 'object' && typeof value !== null) ||
    typeof value === 'function'
  ) {
    return typeof value.then === 'function';
  }
  return false;
}

Promise.all = function (promises) {
  //  如果是个值 存起来就好  如果是个 promise 执行
  return new Promise((resolve, reject) => {
    const arr = [];
    let i = 0;
    const processData = (index, data) => {
      arr[index] = data;
      // 需要等待所有的promise都成功之后，再去掉resolve
      // 异步并发 定时器 每次走的时候
      if (++i === promises.length) {
        //成功
        resolve(arr);
      }
    };
    for (let i = 0; i < promises.length; i++) {
      let current = promises[i];
      //  判断是不是 promise
      if (isPromise(current)) {
        current.then((data) => {
          //  如果有任何一个promise失败了，我们直接让这个priomise变成失败态
          processData(i, data);
        }, reject);
      } else {
        //  注意 Promise.all 要保证顺序 我们不能简单的push 将每一个promise的结果对应起来
        processData(i, current);
      }
    }
  });
};

Promise.all([1, 2, read('./name.txt', 'utf8'), read('./age.txt', 'utf8')]).then(
  (data) => {
    console.log(data, 111);
  },
  (err) => {
    console.log(err, 'err');
  }
);
```

## Promise.resolve/Promise.reject

```js
// 1. Promise.resolve 会等待里面的promise执行成功
// 2. Promise.reject 不会等待里面的promise执行完毕
// resolve的等待效果是如何实现的呢？因为是一个promise，调用resolve会进行递归操作，直到解析出一个普通值
Promise.resolve = function (value) {
  return new Promise((resolve, reject) => {
    resolve(value); // resolve里面放一个promise会等待这个promise执行完
  });
};
// Promise.reject 不会等待里面的promise执行完毕，直接将promise传递给错误的结果
Promise.reject = function (reason) {
  return new Promise((resolve, reject) => {
    reject(reason); // reject 并不会解析 promise值
  });
};
Promise.resolve(
  new Promise((resolve, reject) => {
    setTimeout(() => {
      resolve(1000);
    }, 1000);
  })
).then(
  (data) => {
    console.log(data, 'data');
  },
  (err) => {
    console.log(err, 'err');
  }
);
```

## Promise.prototype.finally

```js
// 无论如何都会执行 还可以跟then 有点类似于catch，其实就是等价的一个then方法
Promise.prototype.finally = function (callback) {
  return this.then(
    (value) => {
      // 我们希望是2s后执行的 等待finally执行完毕后，将上一个成功的结果向下传递
      // callback可能是promise也可能不是
      return Promise.resolve(callback()).then(() => value);
    },
    (err) => {
      return Promise.resolve(callback()).then(() => {
        throw err;
      });
    }
  );
};
Promise.resolve(100)
  .finally(() => {
    return new Promise((resolve, reject) => {
      // 默认会等待当前finally方法的结束
      setTimeout(() => {
        resolve('hello'); // 我这个地方 resolve 这个hello 其实没啥用
      }, 2000);
    });
  })
  .then(
    (data) => {
      console.log(data, 'data');
    },
    (fail) => {
      console.log(fail, 'fail');
    }
  )
  .catch((err) => {
    console.log(err, 'catch');
  });
```

## Promise.race

1. Promise.race 就是默认等到最先得到的 promise 的状态

```js
// 如何让一个promise变成失败态，而不调用这个promise的失败
let p1 = new Promise((resolve, reject) => {
  setTimeout(() => {
    resolve('hello')
  }, 1000)
})
let p2 = new Promise((resolve, reject) => {
  setTimeout(() => {
    reject('hello')
  }, 1900)
})
function isPromise (value) {
  if ((typeof value === 'object' && typeof value !== null) || typeof value === 'function') {
    return typeof value.then === 'function'
  }
  return false
}
Promise.race = function (promises) {
  return new Promise((resolve, reject) => {
    // 谁返回的结果最快就用谁的
    for (let i = 0; i < promises.length; i++) {
      const current = promises[i]
      if (isPromise(current)) { // 采用第一个调用resolve或者reject的结果，注意：promise是都执行了的
        current.then(resolve, reject)
        // current.then(data => {
        //   resolve(data)
        // }, err => {
        //   reject(err)
        // })
      } else {
        resolve(current)
      }
    }
  })
}
2. 应用场景

// 1. 比如说有很多接口  我们要使用返回最快的那个接口 我们就可以使用
// 2. 超时处理
// 这里并不是让p3变成失败态，而是做一个超时处理，超过2s后 不再采用p的成功结果了
// 中断一个 promise 那我是不是让他变成一个失败态
// 具体 2s之后然他超时了，但是3s后的promise还是会执行
let p4 = new Promise((resolve, reject) => {
  setTimeout(() => {
    resolve('3s后 我执行了');
  }, 1000);
});
function wrap(promise) {
  let abort;
  let p = new Promise((resolve, reject) => {
    abort = reject;
  });
  // race方法 来在内部构建了一个promise  将这个promise和传递进来的promise组成了一个race,如果用户调用了 p3的abort方法，相当于
  // 让p3失败了 = promise.race失败了
  let newPromise = Promise.race([p, promise]);
  newPromise.abort = abort;
  return newPromise;
}
let p3 = wrap(p4);
p3.then(
  (data) => {
    console.log('success', data);
  },
  (err) => {
    console.log('err', err);
  }
);
setTimeout(() => {
  // 我们希望调用 abort 的时候将他变为失败态
  p3.abort('2s超时啦');
}, 2000);
```

## 生成器 generator

1. 概念

```js
//generator函数  生成器函数
function* gen() {
  yield 1;
  yield 2;
  //  碰到 return 这个函数参才会结束
}
// 生成的是迭代器对象 -> next -> { value: 1, done: false }
// value 就是当前迭代出来的结果 done标识当前函数是否执行完成
let it = gen();
// 生成器函数和普通函数的区别在于 生成器函数具有暂停的效果 碰到yield就会暂停
console.log(it.next()); // { value: 1, done: false }
console.log(it.next()); // { value: 2, done: false }
console.log(it.next()); //{ value: undefined, done: true }
```

2. 返回值问题

```js
function* gen() {
  let r1 = yield 1;
  console.log(r1);
  let r2 = yield 2;
  console.log(r2);
  return r2;
}
let it = gen();
console.log(it.next(1)); // 第一次传递的值是无效的 因为执行gen前面没有发现yield
console.log(it.next(100)); // 当调用next方法时候传递的参数，会给上次yield赋值
console.log(it.next(200));
// 1. 每次调用next 碰到yield就暂停
// 2. 碰到 return 函数就执行完毕
// 3. 当前调用next时候传递的参数永远给的是上一次yield的返回值
```

3. 应用场景，执行过程

```js
function* read() {
  // 感觉写代码是同步的写 但是执行还是异步嵌套的执行
  const content = yield fs.readFile('./name.txt', 'utf8');
  const age = yield fs.readFile(`./${content}`, 'utf8');
  yield 123;
  return age;
}
// 执行过程 但是如果我们这样一直 往下写不是 回调地狱了嘛 co的实现
let result = read();
let { value, done } = result.next();
value.then((data) => {
  let { value, done } = result.next(data); //data 传递给 content
  value.then((res) => {
    const { value, done } = result.next(res); // 把10传递给 age 碰到return 代码执行完毕
    console.log(value, done);
  });
});
```

## co 的实现过程

```js
function* read() {
  // 感觉写代码是同步的写 但是执行还是异步嵌套的执行
  const content = yield fs.readFile('./name.txt', 'utf8');
  const age = yield fs.readFile(`./${content}`, 'utf8');
  return age;
}
// co的实现
function co(it) {
  return new Promise((resolve, reject) => {
    //  如果是异步 而且是重复性的 不能使用循环 因为循环是同步的
    //  异步重复性工作 迭代 上一次输出下一次的输入 -> 回调 我们自己实现一个
    function next(data) {
      let { value, done } = it.next(data);
      // value有可能是promise也有可能是别的类型 我们 统一转成 Promise 使用 Promise.resolve
      if (!done) {
        Promise.resolve(value).then((data) => {
          next(data);
        }, reject);
      } else {
        resolve(value); // 将最终的结果返回给 当前co的promise
      }
    }

    next();
  });
}
co(read()).then((data) => {
  console.log(data, 'data');
});
```

## async+ await = generator + co

```js
// 用 async + await 模拟 Promise.all
let fn1 = () => {
  return new Promise((resolve, reject) => {
    setTimeout(() => {
      resolve('1');
    }, 1000);
  });
};
let fn2 = () => {
  return new Promise((resolve, reject) => {
    setTimeout(() => {
      resolve('2');
    }, 2000);
  });
};
let fn3 = () => {
  return new Promise((resolve, reject) => {
    setTimeout(() => {
      resolve('3');
    }, 3000);
  });
};
async function asyncAll(promises) {
  const arr = [];
  // forEach是同步的，不具备等待效果
  for (const promise of promises) {
    // 会阻塞for循环 但是我们的promise是一起执行的 所以还是以最长时间为主
    // 第一个成功了 把第一个放进去  第二个成功了 把第二个放进去 这三个一起开的定时器 最长时间3s
    arr.push(await promise); // 走一个 等一个
  }
  return arr;
}

async function readAll() {
  console.log('start time');
  let r = await asyncAll([fn1(), fn2(), fn3()]);
  console.log('end time');
  return r;
}

readAll().then((res) => {
  console.log(res, 'result');
});
```

## then 和 catch 对状态的改变

状态变化会触发 then catch

- pending 不会触发任何 then catch 回调
- 状态变为 resolved 会触发后续的 then 回调
- 状态变为 rejected 会触发后续的 catch 回调

- then 正常返回 resolved 里面有 报错返回 rejected
- catch 正常返回 resolved 里面有报错返回 rejected

---

then catch 会继续返回 Promise ，**此时可能会发生状态变化！！！**

```js
// then() 一般正常返回 resolved 状态的 promise
Promise.resolve().then(() => {
  return 100;
});

// then() 里抛出错误，会返回 rejected 状态的 promise
Promise.resolve().then(() => {
  throw new Error('err');
});

// catch() 不抛出错误，会返回 resolved 状态的 promise
Promise.reject().catch(() => {
  console.error('catch some error');
});

// catch() 抛出错误，会返回 rejected 状态的 promise
Promise.reject().catch(() => {
  console.error('catch some error');
  throw new Error('err');
});
```

看一个综合的例子，即那几个面试题

```js
// 第一题
Promise.resolve()
  .then(() => {
    console.log(1);
  })
  .catch(() => {
    console.log(2);
  })
  .then(() => {
    console.log(3);
  });

// 第二题  虽然是catch返回的结果 但是 状态是resolved的 console.log(3)还是会打印
Promise.resolve()
  .then(() => {
    // 返回 rejected 状态的 promise
    console.log(1);
    throw new Error('erro1');
  })
  .catch(() => {
    // 返回 resolved 状态的 promise
    console.log(2);
  })
  .then(() => {
    console.log(3);
  });

Promise.resolve()
  .then(() => {
    // 返回 rejected 状态的 promise
    console.log(1);
    throw new Error('erro1');
  })
  .catch(() => {
    // 返回 resolved 状态的 promise
    console.log(2);
  })
  .catch(() => {
    //注意 这里是catch 所以不会呗执行
    console.log(3);
  });
```
